<?xml version="1.0" encoding="utf-8"?>
<!-- =================================================================================== -->
<!-- |    This document was autogenerated by xacro from mmrobot.urdf.xacro             | -->
<!-- |    EDITING THIS FILE BY HAND IS NOT RECOMMENDED                                 | -->
<!-- =================================================================================== -->
<robot name="albert">
  <material name="Boxer_Black">
    <color rgba="0.1 0.1 0.1 1.0"/>
  </material>
  <material name="Boxer_Blue">
    <color rgba="0.0 0.0 0.8 1.0"/>
  </material>
  <material name="Boxer_Purple">
    <color rgba="0.6 0.0 0.6 1.0"/>
  </material>
  <material name="Boxer_Green">
    <color rgba="0.0 0.8 0.0 1.0"/>
  </material>
  <material name="Boxer_LimeGreen">
    <color rgba="0.3 0.8 0.3 1.0"/>
  </material>
  <material name="Boxer_Grey">
    <color rgba="0.5 0.5 0.5 1.0"/>
  </material>
  <material name="Boxer_DarkGrey">
    <color rgba="0.3 0.3 0.3 1.0"/>
  </material>
  <material name="Boxer_Red">
    <color rgba="0.8 0.0 0.0 1.0"/>
  </material>
  <material name="Boxer_Pink">
    <color rgba="0.8 0.4 0.8 1.0"/>
  </material>
  <material name="Boxer_White">
    <color rgba="1.0 1.0 1.0 1.0"/>
  </material>
  <material name="Boxer_Yellow">
    <color rgba="0.8 0.8 0.0 1.0"/>
  </material>
  <material name="Boxer_GreyTransparent">
    <color rgba="0.5 0.5 0.5 0.5"/>
  </material>
  <link name="chassis_link">
    <inertial>
      <origin rpy="0 0 0" xyz="0 0 0.07"/>
      <mass value="250"/>
      <inertia ixx="2.3" ixy="0" ixz="0" iyy="3.35" iyz="0.00" izz="1.22"/>
    </inertial>
    <visual>
      <origin rpy="0 0 0" xyz="0 0 0"/>
      <geometry>
        <mesh filename="meshes/visual/chassis_link.dae"/>
      </geometry>
      <material name="">
        <color rgba="0.8 0.8 0.9 1"/>
      </material>
    </visual>
    <collision>
      <origin rpy="0 0 0" xyz="0 0 0"/>
      <geometry>
        <mesh filename="meshes/collision/chassis_link.STL"/>
      </geometry>
    </collision>
  </link>
  <!-- 0.27 in z direction because extrusion is 0.30, and plate is 0.1 -->
  <link name="rotacastor_right_link">
    <inertial>
      <origin rpy="0 0 0" xyz="0 0 0"/>
      <mass value="1"/>
      <inertia ixx="0.2" ixy="0" ixz="0" iyy="0.2" iyz="0" izz="0.2"/>
    </inertial>
    <visual>
      <origin rpy="0 1.5708 0" xyz="0 0 0"/>
      <geometry>
        <cylinder length="0.06" radius="0.0625"/>
      </geometry>
      <material name="Boxer_Red"/>
    </visual>
    <collision>
      <origin rpy="0 1.5708 0" xyz="0 0 0"/>
      <geometry>
        <cylinder length="0.001" radius="0.0625"/>
      </geometry>
    </collision>
  </link>
  <joint name="rotacastor_right_joint" type="continuous">
    <origin rpy="0 0 0" xyz="-0.177 -0.274 0.043"/>
    <parent link="chassis_link"/>
    <child link="rotacastor_right_link"/>
    <axis xyz="1 0 0"/>
    <dynamics damping="1.0"/>
  </joint>
  <link name="rotacastor_left_link">
    <inertial>
      <origin rpy="0 0 0" xyz="0 0 0"/>
      <mass value="1"/>
      <inertia ixx="0.2" ixy="0" ixz="0" iyy="0.2" iyz="0" izz="0.2"/>
    </inertial>
    <visual>
      <origin rpy="0 1.5708 0" xyz="0 0 0"/>
      <geometry>
        <cylinder length="0.06" radius="0.0625"/>
      </geometry>
      <material name="Boxer_Red"/>
    </visual>
    <collision>
      <origin rpy="0 1.5708 0" xyz="0 0 0"/>
      <geometry>
        <cylinder length="0.001" radius="0.0625"/>
      </geometry>
    </collision>
  </link>
  <joint name="rotacastor_left_joint" type="continuous">
    <origin rpy="0 0 0" xyz="0.177 -0.274 0.043"/>
    <parent link="chassis_link"/>
    <child link="rotacastor_left_link"/>
    <axis xyz="1 0 0"/>
    <dynamics damping="1.0"/>
  </joint>
  <link name="wheel_right_link">
    <inertial>
      <origin rpy="0 0 0" xyz="0 0 0"/>
      <mass value="10"/>
      <inertia ixx="0.2" ixy="0" ixz="0" iyy="0.2" iyz="0" izz="0.2"/>
    </inertial>
    <visual>
      <origin rpy="0 1.5708 0" xyz="0 0 0"/>
      <geometry>
        <cylinder length="0.05" radius="0.080"/>
      </geometry>
      <material name="Boxer_Red"/>
    </visual>
    <collision>
      <origin rpy="0 1.5708 0" xyz="0 0 0"/>
      <geometry>
        <cylinder length="0.001" radius="0.080"/>
      </geometry>
    </collision>
  </link>
  <joint name="wheel_right_joint" type="continuous">
    <origin rpy="0 0 0" xyz="-0.247 0.157 0.058"/>
    <parent link="chassis_link"/>
    <child link="wheel_right_link"/>
    <axis xyz="1 0 0"/>
    <limit effort="10000" velocity="1000"/>
    <dynamics damping="1.0"/>
  </joint>
  <link name="wheel_left_link">
    <inertial>
      <origin rpy="0 0 0" xyz="0 0 0"/>
      <mass value="10"/>
      <inertia ixx="0.2" ixy="0" ixz="0" iyy="0.2" iyz="0" izz="0.2"/>
    </inertial>
    <visual>
      <origin rpy="0 1.5708 0" xyz="0 0 0"/>
      <geometry>
        <cylinder length="0.05" radius="0.080"/>
      </geometry>
      <material name="Boxer_Red"/>
    </visual>
    <collision>
      <origin rpy="0 1.5708 0" xyz="0 0 0"/>
      <geometry>
        <cylinder length="0.001" radius="0.080"/>
      </geometry>
    </collision>
  </link>
  <joint name="wheel_left_joint" type="continuous">
    <origin rpy="0 0 0" xyz="0.247 0.157 0.058"/>
    <parent link="chassis_link"/>
    <child link="wheel_left_link"/>
    <axis xyz="1 0 0"/>
    <limit effort="10000" velocity="1000"/>
    <dynamics damping="1.0"/>
  </joint>
  <!-- Base link with no geometry or inertia, because KDL needs it
to be that way. -->
  <link name="base_link_ori">
    <inertial>
      <origin rpy="0 0 0" xyz="0 0 0"/>
      <mass value="0.001"/>
      <inertia ixx="0.2" ixy="0" ixz="0" iyy="0.2" iyz="0" izz="0.2"/>
    </inertial>
  </link>
  <link name="base_link">
    <inertial>
      <origin rpy="0 0 0" xyz="0 0 0"/>
      <mass value="1"/>
      <inertia ixx="0.2" ixy="0" ixz="0" iyy="0.2" iyz="0" izz="0.2"/>
    </inertial>
  </link>
  <joint name="base_chassis_joint" type="fixed">
    <origin rpy="0 0 0" xyz="0 0 0"/>
    <parent link="base_link"/>
    <child link="chassis_link"/>
  </joint>
  <link name="ee_link">
    <visual>
      <origin rpy="0 0 0" xyz="0 0 0"/>
      <geometry>
        <sphere radius="0.0625"/>
      </geometry>
      <material name="Boxer_Red"/>
    </visual>
  </link>
  <joint name="ee_joint" type="fixed">
    <origin rpy="0 0 0" xyz="0 -0.4 0"/>
    <parent link="base_link"/>
    <child link="ee_link"/>
  </joint>
  <joint name="base_add_orientation" type="fixed">
    <origin rpy="0 0 1.57079" xyz="0.0 0 0"/>
    <parent link="base_link_ori"/>
    <child link="base_link"/>
  </joint>
  <!-- end for simulation -->
</robot>

