<?xml version="1.0"?>
<!-- =================================================================================== -->
<!-- |    This document was autogenerated by xacro from panda_arm.urdf.xacro           | -->
<!-- |    EDITING THIS FILE BY HAND IS NOT RECOMMENDED                                 | -->
<!-- =================================================================================== -->


<robot name="pointRobot">
  <material name="blue">
      <color rgba="0 0 0.8 1"/>
  </material>
  <material name="red">
      <color rgba="0.8 0 0.0 1"/>
  </material>
  <link name="world"/>
  <link name="base_link_x">
    <inertial>
      <mass value="1.0"/>
      <origin rpy="0 0 0" xyz="0 0 0"/>
      <inertia ixx="1.0" ixy="0.0" ixz="0.0" iyy="1.0" iyz="0.0" izz="1.0"/>
    </inertial>
  </link>
  <link name="base_link_y">
    <inertial>
      <mass value="1.0"/>
      <origin rpy="0 0 0" xyz="0 0 0"/>
      <inertia ixx="1.0" ixy="0.0" ixz="0.0" iyy="1.0" iyz="0.0" izz="1.0"/>
    </inertial>
  </link>
  <link name="base_link">
    <inertial>
      <mass value="100.0"/>
      <origin rpy="0 0 0" xyz="0 0 0"/>
      <inertia ixx="1.0" ixy="0.0" ixz="0.0" iyy="1.0" iyz="0.0" izz="1.0"/>
    </inertial>
    <collision>
      <origin rpy="0.0 0 0" xyz="0 0 0"/>
      <geometry>
          <cylinder length="0.1" radius="0.2"/>
      </geometry>
    </collision>
    <visual>
      <origin rpy="0.0 0 0" xyz="0 0 0"/>
      <geometry>
          <cylinder length="0.1" radius="0.2"/>
      </geometry>
    </visual>
  </link>
  <link name="lidar_link">
    <inertial>
      <mass value="100.0"/>
      <origin rpy="0 0 0" xyz="0 0 0"/>
      <inertia ixx="1.0" ixy="0.0" ixz="0.0" iyy="1.0" iyz="0.0" izz="1.0"/>
    </inertial>
    <collision>
      <origin rpy="0.0 0 0" xyz="0 0 0"/>
      <geometry>
          <cylinder length="0.1" radius="0.02"/>
      </geometry>
    </collision>
    <visual>
      <origin rpy="0.0 0 0" xyz="0 0 0"/>
      <geometry>
          <cylinder length="0.1" radius="0.02"/>
      </geometry>
      <material name="blue"/>
    </visual>
  </link>
  <link name="feature_link">
    <inertial>
      <mass value="1.0"/>
      <origin rpy="0 0 0" xyz="0 0 0"/>
      <inertia ixx="1.0" ixy="0.0" ixz="0.0" iyy="1.0" iyz="0.0" izz="1.0"/>
    </inertial>
    <collision>
      <origin rpy="0.0 0 0" xyz="0 0 0"/>
      <geometry>
          <cylinder length="0.001" radius="0.02"/>
      </geometry>
    </collision>
    <visual>
      <origin rpy="0.0 0 0" xyz="0 0 0"/>
      <geometry>
          <cylinder length="0.001" radius="0.02"/>
      </geometry>
      <material name="red"/>
    </visual>
  </link>
  <link name="lidar_sensor_link"/>
  <joint name="mobile_joint_x" type="prismatic">
    <safety_controller k_position="100.0" k_velocity="40.0" soft_lower_limit="-2.8973" soft_upper_limit="2.8973"/>
    <parent link="world"/>
    <child link="base_link_x"/>
    <origin rpy="0 0 0" xyz="0 0 0.05"/>
    <axis xyz="1 0 0"/>
    <limit effort="87" lower="-5" upper="5" velocity="2.1750"/>
  </joint>
  <joint name="mobile_joint_y" type="prismatic">
    <safety_controller k_position="100.0" k_velocity="40.0" soft_lower_limit="-2.8973" soft_upper_limit="2.8973"/>
    <parent link="base_link_x"/>
    <child link="base_link_y"/>
    <origin rpy="0 0 0" xyz="0 0 0"/>
    <axis xyz="0 1 0"/>
    <limit effort="87" lower="-5" upper="5" velocity="2.1750"/>
  </joint>
  <joint name="mobile_joint_theta" type="revolute">
    <parent link="base_link_y"/>
    <child link="base_link"/>
    <origin rpy="0 0 0" xyz="0 0 0"/>
    <axis xyz="0 0 1"/>
    <limit effort="87" lower="-5" upper="5" velocity="2.1750"/>
  </joint>
  <joint name="robot_lidar" type="fixed">
    <parent link="base_link"/>
    <child link="lidar_link"/>
    <origin rpy="0 0 0" xyz="0 0 0.1"/>
  </joint>
  <joint name="lidar_sensor_joint" type="fixed">
    <parent link="lidar_link"/>
    <child link="lidar_sensor_link"/>
    <origin rpy="0 0 0" xyz="0 0 0.0"/>
  </joint>
  <joint name="feature_link_joint" type='fixed'>
    <parent link="base_link"/>
    <child link="feature_link"/>
    <origin rpy="0 0 0" xyz="0 0.1 0.0505"/>
  </joint>
  
</robot>
